<mujoco model="drawer">
  <compiler angle="radian" autolimits="true" />
  <option impratio="10" />
  <default>
    <default class="visual">
      <geom type="mesh" contype="0" conaffinity="0" group="2" />
    </default>
    <default class="collision">
      <geom type="mesh" group="3" />
    </default>
  </default>

  <asset>
    <material name="wood" rgba="0.3 0.2 0.05 1" />
  </asset>
  <worldbody>
    <body name="drawer" pos="1.0 0.0 0.0" euler="0 0 3.14">
      <geom size="0.2 0.01 0.28" pos="0 -0.19 0.28" class="visual" type="box" material="wood" />
      <geom size="0.2 0.01 0.28" pos="0 0.19 0.28" class="visual" type="box" material="wood" />
      <geom size="0.2 0.2 0.01" pos="0 0 0.01" class="visual" type="box" material="wood" />
      <geom size="0.2 0.2 0.01" pos="0 0 0.55" class="visual" type="box" material="wood" />
      <geom size="0.01 0.2 0.28" pos="-0.19 0 0.28" class="visual" type="box" material="wood" />


      <geom size="0.2 0.01 0.28" pos="0 -0.19 0.28" class="collision" type="box" />
      <geom size="0.2 0.01 0.28" pos="0 0.19 0.28" class="collision" type="box" />
      <geom size="0.2 0.2 0.01" pos="0 0 0.01" class="collision" type="box" />
      <geom size="0.2 0.2 0.01" pos="0 0 0.55" class="collision" type="box" />
      <geom size="0.01 0.2 0.28" pos="-0.19 0 0.28" class="collision" type="box" />


      <body name="bottom_drawer" pos="0.03 0 0.11">
        <joint name="bottom_drawer_slide" type="slide" axis="1 0 0" limited="true" range="0 0.3"
          damping="50.0" frictionloss="1.0" />

        <!-- bottom -->
        <geom size="0.17 0.17 0.01" class="visual" type="box" pos="0 0 -0.07" material="wood" />
        <!-- left and right -->
        <geom size="0.17 0.01 0.08" class="visual" type="box" pos="0 0.16 0" material="wood" />
        <geom size="0.17 0.01 0.08" class="visual" type="box" pos="0 -0.16 0" material="wood" />
        <!-- front and back -->
        <geom size="0.01 0.17 0.08" class="visual" type="box" pos="0.16 0 0" material="wood" />
        <geom size="0.01 0.17 0.08" class="visual" type="box" pos="-0.16 0 0" material="wood" />

        <!-- bottom -->
        <geom size="0.17 0.17 0.01" class="collision" type="box" pos="0 0 -0.07" />
        <!-- left and right -->
        <geom size="0.17 0.01 0.08" class="collision" type="box" pos="0 0.16 0" />
        <geom size="0.17 0.01 0.08" class="collision" type="box" pos="0 -0.16 0" />
        <!-- front and back -->
        <geom size="0.01 0.17 0.08" class="collision" type="box" pos="0.16 0 0" />
        <geom size="0.01 0.17 0.08" class="collision" type="box" pos="-0.16 0 0" />

        <body name="bottom_drawer_handle" pos="0.2 0 0" euler="1.57 0 0">
          <geom size="0.01 0.05" class="visual" type="cylinder" material="wood" />
          <geom size="0.01 0.05" class="collision" type="cylinder" />
        </body>
      </body>
      <body name="middle_drawer" pos="0.03 0 0.28">
        <joint name="middle_drawer_slide" type="slide" axis="1 0 0" limited="true" range="0 0.3"
          damping="50.0" frictionloss="1.0" />

        <!-- bottom -->
        <geom size="0.17 0.17 0.01" class="visual" type="box" pos="0 0 -0.07" material="wood" />
        <!-- left and right -->
        <geom size="0.17 0.01 0.08" class="visual" type="box" pos="0 0.16 0" material="wood" />
        <geom size="0.17 0.01 0.08" class="visual" type="box" pos="0 -0.16 0" material="wood" />
        <!-- front and back -->
        <geom size="0.01 0.17 0.08" class="visual" type="box" pos="0.16 0 0" material="wood" />
        <geom size="0.01 0.17 0.08" class="visual" type="box" pos="-0.16 0 0" material="wood" />

        <!-- bottom -->
        <geom size="0.17 0.17 0.01" class="collision" type="box" pos="0 0 -0.07" />
        <!-- left and right -->
        <geom size="0.17 0.01 0.08" class="collision" type="box" pos="0 0.16 0" />
        <geom size="0.17 0.01 0.08" class="collision" type="box" pos="0 -0.16 0" />
        <!-- front and back -->
        <geom size="0.01 0.17 0.08" class="collision" type="box" pos="0.16 0 0" />
        <geom size="0.01 0.17 0.08" class="collision" type="box" pos="-0.16 0 0" />

        <body name="middle_drawer_handle" pos="0.2 0 0" euler="1.57 0 0">
          <geom size="0.01 0.05" class="visual" type="cylinder" material="wood" />
          <geom size="0.01 0.05" class="collision" type="cylinder" />
        </body>
      </body>
      <body name="top_drawer" pos="0.03 0 0.45">
        <joint name="top_drawer_slide" type="slide" axis="1 0 0" limited="true" range="0 0.3"
          damping="50.0" frictionloss="1.0" />

        <!-- bottom -->
        <geom size="0.17 0.17 0.01" class="visual" type="box" pos="0 0 -0.07" material="wood" />
        <!-- left and right -->
        <geom size="0.17 0.01 0.08" class="visual" type="box" pos="0 0.16 0" material="wood" />
        <geom size="0.17 0.01 0.08" class="visual" type="box" pos="0 -0.16 0" material="wood" />
        <!-- front and back -->
        <geom size="0.01 0.17 0.08" class="visual" type="box" pos="0.16 0 0" material="wood" />
        <geom size="0.01 0.17 0.08" class="visual" type="box" pos="-0.16 0 0" material="wood" />

        <!-- bottom -->
        <geom size="0.17 0.17 0.01" class="collision" type="box" pos="0 0 -0.07" />
        <!-- left and right -->
        <geom size="0.17 0.01 0.08" class="collision" type="box" pos="0 0.16 0" />
        <geom size="0.17 0.01 0.08" class="collision" type="box" pos="0 -0.16 0" />
        <!-- front and back -->
        <geom size="0.01 0.17 0.08" class="collision" type="box" pos="0.16 0 0" />
        <geom size="0.01 0.17 0.08" class="collision" type="box" pos="-0.16 0 0" />

        <body name="top_drawer_handle" pos="0.2 0 0" euler="1.57 0 0">
          <geom size="0.01 0.05" class="visual" type="cylinder" material="wood" />
          <geom size="0.01 0.05" class="collision" type="cylinder" />
        </body>
      </body>
    </body>

  </worldbody>
</mujoco>
  